Traceback (most recent call last):
  File "/Users/nt/main_env/lib/python3.12/site-packages/psutil/_psosx.py", line 349, in wrapper
    return fun(self, *args, **kwargs)
           ^^^^^^^^^^^^^^^^^^^^^^^^^^
  File "/Users/nt/main_env/lib/python3.12/site-packages/psutil/_common.py", line 508, in wrapper
    raise raise_from(err, None)
          ^^^^^^^^^^^^^^^^^^^^^
  File "<string>", line 3, in raise_from
  File "/Users/nt/main_env/lib/python3.12/site-packages/psutil/_common.py", line 506, in wrapper
    return fun(self)
           ^^^^^^^^^
  File "/Users/nt/main_env/lib/python3.12/site-packages/psutil/_psosx.py", line 375, in _get_kinfo_proc
    ret = cext.proc_kinfo_oneshot(self.pid)
          ^^^^^^^^^^^^^^^^^^^^^^^^^^^^^^^^^
ProcessLookupError: [Errno 3] assume no such process (originated from sysctl(kinfo_proc), len == 0)

During handling of the above exception, another exception occurred:

Traceback (most recent call last):
  File "/Users/nt/main_env/lib/python3.12/site-packages/psutil/__init__.py", line 355, in _init
    self._ident = self._get_ident()
                  ^^^^^^^^^^^^^^^^^
  File "/Users/nt/main_env/lib/python3.12/site-packages/psutil/__init__.py", line 396, in _get_ident
    return (self.pid, self.create_time())
                      ^^^^^^^^^^^^^^^^^^
  File "/Users/nt/main_env/lib/python3.12/site-packages/psutil/__init__.py", line 778, in create_time
    self._create_time = self._proc.create_time()
                        ^^^^^^^^^^^^^^^^^^^^^^^^
  File "/Users/nt/main_env/lib/python3.12/site-packages/psutil/_psosx.py", line 349, in wrapper
    return fun(self, *args, **kwargs)
           ^^^^^^^^^^^^^^^^^^^^^^^^^^
  File "/Users/nt/main_env/lib/python3.12/site-packages/psutil/_psosx.py", line 477, in create_time
    return self._get_kinfo_proc()[kinfo_proc_map['ctime']]
           ^^^^^^^^^^^^^^^^^^^^^^
  File "/Users/nt/main_env/lib/python3.12/site-packages/psutil/_psosx.py", line 354, in wrapper
    raise NoSuchProcess(self.pid, self._name)
psutil.NoSuchProcess: process no longer exists (pid=1622)

During handling of the above exception, another exception occurred:

Traceback (most recent call last):
  File "/Users/nt/main_env/bin/airflow", line 8, in <module>
    sys.exit(main())
             ^^^^^^
  File "/Users/nt/main_env/lib/python3.12/site-packages/airflow/__main__.py", line 58, in main
    args.func(args)
  File "/Users/nt/main_env/lib/python3.12/site-packages/airflow/cli/cli_config.py", line 49, in command
    return func(*args, **kwargs)
           ^^^^^^^^^^^^^^^^^^^^^
  File "/Users/nt/main_env/lib/python3.12/site-packages/airflow/utils/cli.py", line 114, in wrapper
    return f(*args, **kwargs)
           ^^^^^^^^^^^^^^^^^^
  File "/Users/nt/main_env/lib/python3.12/site-packages/airflow/utils/providers_configuration_loader.py", line 55, in wrapped_function
    return func(*args, **kwargs)
           ^^^^^^^^^^^^^^^^^^^^^
  File "/Users/nt/main_env/lib/python3.12/site-packages/airflow/cli/commands/webserver_command.py", line 485, in webserver
    run_command_with_daemon_option(
  File "/Users/nt/main_env/lib/python3.12/site-packages/airflow/cli/commands/daemon_utils.py", line 80, in run_command_with_daemon_option
    callback()
  File "/Users/nt/main_env/lib/python3.12/site-packages/airflow/cli/commands/webserver_command.py", line 488, in <lambda>
    callback=lambda: start_and_monitor_gunicorn(args),
                     ^^^^^^^^^^^^^^^^^^^^^^^^^^^^^^^^
  File "/Users/nt/main_env/lib/python3.12/site-packages/airflow/cli/commands/webserver_command.py", line 471, in start_and_monitor_gunicorn
    gunicorn_master_proc = psutil.Process(gunicorn_master_proc_pid)
                           ^^^^^^^^^^^^^^^^^^^^^^^^^^^^^^^^^^^^^^^^
  File "/Users/nt/main_env/lib/python3.12/site-packages/psutil/__init__.py", line 319, in __init__
    self._init(pid)
  File "/Users/nt/main_env/lib/python3.12/site-packages/psutil/__init__.py", line 368, in _init
    raise NoSuchProcess(pid, msg=msg)
psutil.NoSuchProcess: process PID not found (pid=1622)
